Workbook

Sheet ReadMe
A1: 1) All currency unit is in US dollar ($)
A2: 2) One netting set can only link to one CSA
A4: Trade inputs headers | B4: Description | C4: CSA inputs headers | D4: Description
A5: Trade_ID | B5: Trade ID | C5: Netting_ID | D5: Netting Set ID
A6: Netting_ID | B6: Netting Set ID | C6: Margin_ID | D6: Margin Agreement ID
A7: Underlying_ticker | B7: The risk driver of the trade: 1) For equity, please type in the reference entity like "SP500", "AAPL" etc. 2) For credit, please type in the reference entity of issuer like "BA", "MS" etc. 3) For interest rate: please type in the reference currency like "USD", "JPY" etc. 4) For FX, please type in the reference currency pair like "USD_CAD", "USD_JPY" etc. Please keep the format consistent through all FX trades. 5) For commodity, please type in commodity type like "Crude Oil", "Natural Gas", "AU", "Sugar" etc. 6) For volatility based trade, please type in the underlying ticker on which volatility contract is based on and in the same way as 1) to 5). Like "SP500", "USD" etc. 7) For basis trade, please type in the corresponding basis pair, like "USD1y_USD3m" | C7: Margin_status | D7: Please type in "Margined" or "Unmargined"
A8: Long_Short | B8: Please type in "Long" or "Short" For CDO products, "Long" indicates purchasing credit protection and "Short" indicates selling credit protection. | C8: NICA | D8: Net independent collateral amount (NICA). NICA represents any collateral (segregated or unsegregated) posted by the counterparty less the unsegregated collateral posted by the bank. The input amount is assumed to be post haircut if any.
A9: Asset_class | B9: Asset class of underlying ticker (select on from parameters tab Asset_class column) | C9: VM | D9: Net variation margin amount, where the amount received by the bank is accounted with a positive sign and the amount posted by the bank is accounted with a negative sign. Leave it empty if not applicatble. The input amount is assumed to be post haircut if any.
A10: Category | B10: Asset category of underlying ticker (select on from parameters tab Category column) | C10: VMT | D10: Variation margin threshold. Leave it empty if not applicatble.
A11: Type | B11: Asset type of underlying ticker (select on from parameters tab Type column) | C11: MTA | D11: Minimum transfer amount. Leave it empty if not applicatble.
A12: Market_value | B12: Markte value of this trade (negative value for short)
A13: Trade_notional | B13: Notional of the trade
A14: MPOR | B14: Market Period of Risk (business days). Leave it empty if not applicatble.
A15: start_date | B15: the number of business days from the present day until the start date of the derivative contract, or zero if the start date has already passed.
A16: end_date | B16: the number of business days from the present day until the end date of the derivative contract.
A17: Maturity | B17: Maturity of the derivative contract (business days)
A18: is_option | B18: Please type in "TRUE" or "FALSE" to indicate if this trade is on options
A19: Call_Put | B19: Please type in "Call" or "Put" for an options trade
A20: Underlying_price | B20: Underlying price of options trades in USD. Leave it empty if not applicatble.
A21: Strike_price | B21: Strike price of options trades in USD. Leave it empty if not applicatble.
A22: Option_maturity | B22: Maturity of options trades (business days). Leave it empty if not applicatble.
A23: is_CDO_tranches | B23: Please type in "TRUE" or "FALSE" to indicate if this trade is on CDO
... A27: is_basis_trade | B27: Please type in "TRUE" or "FALSE" to indicate if this trade is a basis trade on the underlying ticker

Sheet trades_inputs
A1: Trade_ID | B1: Netting_ID | C1: Underlying_ticker | D1: Long_Short | E1: Asset_class | F1: Category | G1: Type | H1: Market_value | I1: Trade_notional | J1: MPOR | K1: start_date | L1: end_date | M1: Maturity | N1: is_option | O1: Call_Put | P1: Underlying_price | Q1: Strike_price | R1: Option_maturity | S1: is_CDO_tranches | T1: Attachment_Point | U1: Detachment_Point | V1: is_volatility_trade | W1: is_basis_trade | X1: COB_date | Y1: System_end_date | Z1: System_delta | AA1: is_client_facing | AB1: margin frequency (BD) | AC1: is_large_netting_set | AD1: ns_has_difficult_to_replace_trade | AE1: ns_has_illiquid_collateral | AF1: margin_dispute
A2: Trade_001 | B2: MNA001 | C2: USD | D2: Short | E2: Interest rate | F2: N/A | G2: N/A | H2: -11107 | I2: 9000000 | J2: 10 | K2: 0 | L2: 2353 | M2: 2353 | N2: FALSE | S2: FALSE | V2: FALSE | W2: FALSE | X2: 45838 | Y2: =X2+L2 -> 48191 | Z2: -1 | AA2: N | AB2: 1 | AC2: N | AD2: N | AE2: N | AF2: N
A3: Trade_002 | B3: MNA001 | C3: USD | D3: Short | E3: Interest rate | F3: N/A | G3: N/A | H3: -16660 | I3: 36000000 | J3: 10 | K3: 0 | L3: 961 | M3: 961 | N3: FALSE | S3: FALSE | V3: FALSE | W3: FALSE | X3: 45838 | Y3: =X3+L3 -> 46799 | Z3: -1 | AA3: N | AB3: 1 | AC3: N | AD3: N | AE3: N | AF3: N
A4: Trade_003 | B4: MNA001 | C4: USD | D4: Short | E4: Interest rate | F4: N/A | G4: N/A | H4: -5553 | I4: 4000000 | J4: 10 | K4: 0 | L4: 199 | M4: 199 | N4: FALSE | S4: FALSE | V4: FALSE | W4: FALSE | X4: 45838 | Y4: =X4+L4 -> 46037 | Z4: -1 | AA4: N | AB4: 1 | AC4: N | AD4: N | AE4: N | AF4: N
A5: Trade_004 | B5: MNA001 | C5: CD:1485537 | D5: Long | E5: Credit, single name | F5: Investment grade | G5: N/A | H5: 135000 | I5: 300000 | J5: 10 | K5: 0 | L5: 65 | M5: 65 | N5: FALSE | S5: FALSE | V5: FALSE | W5: FALSE | X5: 45838 | Y5: =X5+L5 -> 45903 | Z5: 1 | AA5: N | AB5: 1 | AC5: N | AD5: N | AE5: N | AF5: N
A6: Trade_005 | B6: MNA001 | C6: CD:index 119 | D6: Long | E6: Credit, index | F6: Speculative grade | G6: N/A | H6: 70040 | I6: 760473 | J6: 10 | K6: 251 | L6: 1068 | M6: 251 | N6: TRUE | O6: Call | P6: 0.007483 | Q6: 0.03 | R6: 251 | S6: FALSE | V6: FALSE | W6: FALSE | X6: 45838 | Y6: =X6+L6 -> 46906 | Z6: 0.091521436 | AA6: N | AB6: 1 | AC6: N | AD6: N | AE6: N | AF6: N
A7: Trade_006 | B7: MNA001 | C7: AUD_USD | D7: Short | E7: Exchange rate | F7: N/A | G7: N/A | H7: -8291 | I7: 131766.9 | J7: 10 | K7: 0 | L7: 158 | M7: 158 | N7: FALSE | S7: FALSE | V7: FALSE | W7: FALSE | X7: 45838 | Y7: =X7+L7 -> 45996 | Z7: -1 | AA7: N | AB7: 1 | AC7: N | AD7: N | AE7: N | AF7: N
A8: Trade_007 | B8: MNA001 | C8: CAD_USD | D8: Short | E8: Exchange rate | F8: N/A | G8: N/A | H8: -5300 | I8: 27663.04 | J8: 10 | K8: 0 | L8: 220 | M8: 220 | N8: FALSE | S8: FALSE | V8: FALSE | W8: FALSE | X8: 45838 | Y8: =X8+L8 -> 46058 | Z8: -1 | AA8: N | AB8: 1 | AC8: N | AD8: N | AE8: N | AF8: N
A9: Trade_008 | B9: MNA001 | C9: SP500 | D9: Long | E9: Equity, index | F9: N/A | G9: N/A | H9: 813000 | I9: 6883500 | J9: 10 | K9: 0 | L9: 250 | M9: 250 | N9: TRUE | O9: Call | P9: 4589 | Q9: 4589 | R9: 250 | S9: FALSE | V9: FALSE | W9: FALSE | X9: 45838 | Y9: =X9+L9 -> 46088 | Z9: 0.64616977 | AA9: N | AB9: 1 | AC9: N | AD9: N | AE9: N | AF9: N
A10: Trade_009 | B10: MNA001 | C10: STOXX50 | D10: Short | E10: Equity, index | F10: N/A | G10: N/A | H10: -459120 | I10: 5139168 | J10: 10 | K10: 0 | L10: 250 | M10: 250 | N10: TRUE | O10: Call | P10: 4282.64 | Q10: 4282.64 | R10: 250 | S10: FALSE | V10: FALSE | W10: FALSE | X10: 45838 | Y10: =X10+L10 -> 46088 | Z10: -0.64616977 | AA10: N | AB10: 1 | AC10: N | AD10: N | AE10: N | AF10: N
A11: Trade_010 | B11: MNA001 | C11: Henry Hub | D11: Long | E11: Commodity | F11: Energy | G11: Other | H11: 400800 | I11: 964228 | J11: 10 | K11: 0 | L11: 125 | M11: 125 | N11: TRUE | O11: Call | P11: 120 | Q11: 120 | R11: 125 | S11: FALSE | V11: FALSE | W11: FALSE | X11: 45838 | Y11: =X11+L11 -> 45963 | Z11: 0.59773447 | AA11: N | AB11: 1 | AC11: N | AD11: N | AE11: N | AF11: N
A12: Trade_011 | B12: MNA001 | C12: Electricity | D12: Short | E12: Commodity | F12: Energy | G12: Electricity | H12: -365500 | I12: 951770 | J12: 10 | K12: 0 | L12: 125 | M12: 125 | N12: FALSE | S12: FALSE | V12: FALSE | W12: FALSE | X12: 45838 | Y12: =X12+L12 -> 45963 | Z12: -1 | AA12: N | AB12: 1 | AC12: N | AD12: N | AE12: N | AF12: N
A13: Trade_012 | B13: MNA001 | C13: Cattle | D13: Short | E13: Commodity | F13: Other | G13: N/A | H13: -423000 | I13: 357821 | J13: 10 | K13: 0 | L13: 125 | M13: 125 | N13: FALSE | S13: FALSE | V13: FALSE | W13: FALSE | X13: 45838 | Y13: =X13+L13 -> 45963 | Z13: -1 | AA13: N | AB13: 1 | AC13: N | AD13: N | AE13: N | AF13: N
A14: Trade_013 | B14: MNA001 | C14: Soybean | D14: Long | E14: Commodity | F14: Agricultural | G14: N/A | H14: 725649 | I14: 342599 | J14: 10 | K14: 0 | L14: 125 | M14: 125 | N14: FALSE | S14: FALSE | V14: FALSE | W14: FALSE | X14: 45838 | Y14: =X14+L14 -> 45963 | Z14: 1 | AA14: N | AB14: 1 | AC14: N | AD14: N | AE14: N | AF14: N
A15: Trade_014 | B15: MNA001 | C15: Gold | D15: Long | E15: Commodity | F15: Metals | G15: N/A | H15: 542000 | I15: 1925621 | J15: 10 | K15: 250 | L15: 500 | M15: 250 | N15: FALSE | S15: FALSE | V15: FALSE | W15: FALSE | X15: 45838 | Y15: =X15+L15 -> 46338 | Z15: 1 | AA15: N | AB15: 1 | AC15: N | AD15: N | AE15: N | AF15: N
A16: Trade_001 | B16: MNA002 | C16: USD1y_USD3m | D16: Long | E16: Interest rate | F16: N/A | G16: N/A | H16: 11107 | I16: 9000000 | J16: 40 | K16: 0 | L16: 2353 | M16: 2353 | N16: FALSE | S16: FALSE | V16: FALSE | W16: TRUE | X16: 45838 | Y16: =X16+L16 -> 48191 | Z16: 1 | AA16: N | AB16: 1 | AC16: N | AD16: Y | AE16: N | AF16: Y
A17: Trade_002 | B17: MNA002 | C17: USD | D17: Long | E17: Interest rate | F17: N/A | G17: N/A | H17: 11107 | I17: 9000000 | J17: 40 | K17: 0 | L17: 2353 | M17: 2353 | N17: FALSE | S17: FALSE | V17: TRUE | W17: FALSE | X17: 45838 | Y17: =X17+L17 -> 48191 | Z17: 1 | AA17: N | AB17: 1 | AC17: N | AD17: Y | AE17: N | AF17: Y
A18: Trade_003 | B18: MNA002 | C18: USD | D18: Long | E18: Interest rate | F18: N/A | G18: N/A | H18: 11107 | I18: 9000000 | J18: 40 | K18: 0 | L18: 2353 | M18: 2353 | N18: FALSE | S18: FALSE | V18: FALSE | W18: FALSE | X18: 45838 | Y18: =X18+L18 -> 48191 | Z18: 1 | AA18: N | AB18: 1 | AC18: N | AD18: Y | AE18: N | AF18: Y
A19: Trade_004 | B19: MNA002 | C19: USD | D19: Long | E19: Interest rate | F19: N/A | G19: N/A | H19: 16660 | I19: 36000000 | J19: 40 | K19: 0 | L19: 961 | M19: 961 | N19: FALSE | S19: FALSE | V19: FALSE | W19: FALSE | X19: 45838 | Y19: =X19+L19 -> 46799 | Z19: 1 | AA19: N | AB19: 1 | AC19: N | AD19: Y | AE19: N | AF19: Y
A20: Trade_005 | B20: MNA002 | C20: USD | D20: Long | E20: Interest rate | F20: N/A | G20: N/A | H20: 5553 | I20: 4000000 | J20: 40 | K20: 0 | L20: 199 | M20: 199 | N20: FALSE | S20: FALSE | V20: FALSE | W20: FALSE | X20: 45838 | Y20: =X20+L20 -> 46037 | Z20: 1 | AA20: N | AB20: 1 | AC20: N | AD20: Y | AE20: N | AF20: Y
A21: Trade_006 | B21: MNA002 | C21: AP_CDO_equity_tranche | D21: Short | E21: Credit, single name | F21: Speculative grade | G21: N/A | H21: -25040 | I21: 5506800 | J21: 40 | K21: 0 | L21: 250 | M21: 250 | N21: FALSE | S21: TRUE | T21: 0 | U21: 0.04 | V21: FALSE | W21: FALSE | X21: 45838 | Y21: =X21+L21 -> 46088 | Z21: -9.6153846 | AA21: N | AB21: 1 | AC21: N | AD21: Y | AE21: N | AF21: Y
A22: Trade_001 | B22: MNA003 | C22: SP500 | D22: Long | E22: Equity, index | F22: N/A | G22: N/A | H22: 813000 | I22: 6883500 | K22: 0 | L22: 250 | M22: 250 | N22: TRUE | O22: Call | P22: 4589 | Q22: 4589 | R22: 250 | S22: FALSE | V22: FALSE | W22: FALSE | X22: 45838 | Y22: =X22+L22 -> 46088 | Z22: 0.64616977 | AA22: N | AB22: 1 | AC22: N | AD22: N | AE22: N | AF22: N
A23: Trade_002 | B23: MNA003 | C23: STOXX50 | D23: Long | E23: Equity, index | F23: N/A | G23: N/A | H23: -459120 | I23: 5139168 | K23: 0 | L23: 250 | M23: 250 | N23: TRUE | O23: Call | P23: 4282.64 | Q23: 4282.64 | R23: 250 | S23: FALSE | V23: FALSE | W23: FALSE | X23: 45838 | Y23: =X23+L23 -> 46088 | Z23: 0.64616977 | AA23: N | AB23: 1 | AC23: N | AD23: N | AE23: N | AF23: N
A24: Trade_003 | B24: MNA003 | C24: AUD_USD | D24: Short | E24: Exchange rate | F24: N/A | G24: N/A | H24: -8291 | I24: 131766.9 | K24: 0 | L24: 158 | M24: 158 | N24: FALSE | S24: FALSE | V24: FALSE | W24: FALSE | X24: 45838 | Y24: =X24+L24 -> 45996 | Z24: -1 | AA24: N | AB24: 1 | AC24: N | AD24: N | AE24: N | AF24: N
A25: Trade_004 | B25: MNA003 | C25: CAD_USD | D25: Short | E25: Exchange rate | F25: N/A | G25: N/A | H25: -5300 | I25: 27663.04 | K25: 0 | L25: 220 | M25: 220 | N25: FALSE | S25: FALSE | V25: FALSE | W25: FALSE | X25: 45838 | Y25: =X25+L25 -> 46058 | Z25: -1 | AA25: N | AB25: 1 | AC25: N | AD25: N | AE25: N | AF25: N
A26: Trade_001 | B26: MNA004 | C26: SP500 | D26: Long | E26: Equity, index | F26: N/A | G26: N/A | H26: 813000 | I26: 6883500 | J26: 10 | K26: 0 | L26: 250 | M26: 250 | N26: TRUE | O26: Call | P26: 4589 | Q26: 4589 | R26: 250 | S26: FALSE | V26: FALSE | W26: FALSE | X26: 45838 | Y26: =X26+L26 -> 46088 | Z26: 0.64616977 | AA26: N | AB26: 1 | AC26: N | AD26: N | AE26: N | AF26: N
A27: Trade_002 | B27: MNA004 | C27: STOXX50 | D27: Long | E27: Equity, index | F27: N/A | G27: N/A | H27: -459120 | I27: 5139168 | J27: 10 | K27: 0 | L27: 250 | M27: 250 | N27: TRUE | O27: Call | P27: 4282.64 | Q27: 4282.64 | R27: 250 | S27: FALSE | V27: FALSE | W27: FALSE | X27: 45838 | Y27: =X27+L27 -> 46088 | Z27: 0.64616977 | AA27: N | AB27: 1 | AC27: N | AD27: N | AE27: N | AF27: N
A28: Trade_003 | B28: MNA004 | C28: AUD_USD | D28: Short | E28: Exchange rate | F28: N/A | G28: N/A | H28: -8291 | I28: 131766.9 | J28: 10 | K28: 0 | L28: 158 | M28: 158 | N28: FALSE | S28: FALSE | V28: FALSE | W28: FALSE | X28: 45838 | Y28: =X28+L28 -> 45996 | Z28: -1 | AA28: N | AB28: 1 | AC28: N | AD28: N | AE28: N | AF28: N
A29: Trade_004 | B29: MNA004 | C29: CAD_USD | D29: Short | E29: Exchange rate | F29: N/A | G29: N/A | H29: -5300 | I29: 27663.04 | J29: 10 | K29: 0 | L29: 220 | M29: 220 | N29: FALSE | S29: FALSE | V29: FALSE | W29: FALSE | X29: 45838 | Y29: =X29+L29 -> 46058 | Z29: -1 | AA29: N | AB29: 1 | AC29: N | AD29: N | AE29: Y | AF29: Y
A30: Trade_001 | B30: MNA005 | C30: USD1y_USD3m | D30: Long | E30: Interest rate | F30: N/A | G30: N/A | H30: 11107 | I30: 9000000 | J30: 40 | K30: 0 | L30: 2353 | M30: 2353 | N30: FALSE | S30: FALSE | V30: FALSE | W30: TRUE | X30: 45838 | Y30: 45838 | Z30: 1 | AA30: N | AB30: 1 | AC30: N | AD30: N | AE30: Y | AF30: Y
A31: Trade_002 | B31: MNA005 | C31: USD | D31: Long | E31: Interest rate | F31: N/A | G31: N/A | H31: 11107 | I31: 9000000 | J31: 40 | K31: 0 | L31: 2353 | M31: 2353 | N31: FALSE | S31: FALSE | V31: TRUE | W31: FALSE | X31: 45838 | Y31: =X31+L31 -> 48191 | Z31: 1 | AA31: N | AB31: 1 | AC31: N | AD31: N | AE31: Y | AF31: Y
A32: Trade_003 | B32: MNA005 | C32: USD | D32: Long | E32: Interest rate | F32: N/A | G32: N/A | H32: 11107 | I32: 9000000 | J32: 40 | K32: 0 | L32: 2353 | M32: 2353 | N32: FALSE | S32: FALSE | V32: FALSE | W32: FALSE | X32: 45838 | Y32: =X32+L32 -> 48191 | Z32: 1 | AA32: N | AB32: 1 | AC32: N | AD32: N | AE32: Y | AF32: Y
A33: Trade_004 | B33: MNA005 | C33: USD | D33: Long | E33: Interest rate | F33: N/A | G33: N/A | H33: 16660 | I33: 36000000 | J33: 40 | K33: 0 | L33: 961 | M33: 961 | N33: FALSE | S33: FALSE | V33: FALSE | W33: FALSE | X33: 45838 | Y33: =X33+L33 -> 46799 | Z33: 1 | AA33: N | AB33: 1 | AC33: N | AD33: N | AE33: Y | AF33: Y
A34: Trade_005 | B34: MNA005 | C34: USD | D34: Long | E34: Interest rate | F34: N/A | G34: N/A | H34: 5553 | I34: 4000000 | J34: 40 | K34: 0 | L34: 199 | M34: 199 | N34: FALSE | S34: FALSE | V34: FALSE | W34: FALSE | X34: 45838 | Y34: =X34+L34 -> 46037 | Z34: 1 | AA34: N | AB34: 1 | AC34: N | AD34: N | AE34: Y | AF34: Y
A35: Trade_006 | B35: MNA005 | C35: AP_CDO_equity_tranche | D35: Short | E35: Credit, single name | F35: Speculative grade | G35: N/A | H35: -25040 | I35: 5506800 | J35: 40 | K35: 0 | L35: 250 | M35: 250 | N35: FALSE | S35: TRUE | T35: 0 | U35: 0.04 | V35: FALSE | W35: FALSE | X35: 45838 | Y35: =X35+L35 -> 46088 | Z35: -9.6153846 | AA35: N | AB35: 1 | AC35: N | AD35: N | AE35: Y | AF35: Y
A36: Trade_001 | B36: MNA006 | C36: STOXX50 | D36: Short | E36: Equity, index | F36: N/A | G36: N/A | H36: -459120 | I36: 5139168 | J36: 10 | K36: 0 | L36: 250 | M36: 250 | N36: TRUE | O36: Call | P36: 4282.64 | Q36: 4282.64 | R36: 250 | S36: FALSE | V36: FALSE | W36: FALSE | X36: 45838 | Y36: =X36+L36 -> 46088 | Z36: -3 | AA36: N | AB36: 1 | AC36: N | AD36: N | AE36: N | AF36: N
A37: Trade_001 | B37: MNA007 | C37: USD1y_USD3m | D37: Long | E37: Interest rate | F37: N/A | G37: N/A | H37: 11107 | I37: 9000000 | J37: 40 | K37: 0 | L37: 2353 | M37: 2353 | N37: FALSE | S37: FALSE | V37: FALSE | W37: TRUE | X37: 45838 | Y37: 45838 | Z37: 1 | AA37: N | AB37: 1 | AC37: N | AD37: N | AE37: Y | AF37: N
A38: Trade_002 | B38: MNA007 | C38: USD | D38: Long | E38: Interest rate | F38: N/A | G38: N/A | H38: 11107 | I38: 9000000 | J38: 40 | K38: 0 | L38: 2353 | M38: 2353 | N38: FALSE | S38: FALSE | V38: TRUE | W38: FALSE | X38: 45838 | Y38: =X38+L38 -> 48191 | Z38: 1 | AA38: N | AB38: 1 | AC38: N | AD38: N | AE38: Y | AF38: N
A39: Trade_003 | B39: MNA007 | C39: USD | D39: Long | E39: Interest rate | F39: N/A | G39: N/A | H39: 11107 | I39: 9000000 | J39: 40 | K39: 0 | L39: 2353 | M39: 2353 | N39: FALSE | S39: FALSE | V39: FALSE | W39: FALSE | X39: 45838 | Y39: =X39+L39 -> 48191 | Z39: 1 | AA39: N | AB39: 1 | AC39: N | AD39: N | AE39: Y | AF39: N
A40: Trade_004 | B40: MNA007 | C40: USD | D40: Long | E40: Interest rate | F40: N/A | G40: N/A | H40: 16660 | I40: 36000000 | J40: 40 | K40: 0 | L40: 961 | M40: 961 | N40: FALSE | S40: FALSE | V40: FALSE | W40: FALSE | X40: 45838 | Y40: =X40+L40 -> 46799 | Z40: 1 | AA40: N | AB40: 1 | AC40: N | AD40: N | AE40: Y | AF40: N
...

Sheet csa_inputs
A1: Netting_ID | B1: Margin_ID | C1: Margin_status | D1: NICA | E1: VM | F1: VMT | G1: MTA | H1: System_EAD
A2: MNA001 | B2: CSA_001 | C2: Margined | D2: 853000 | E2: 1300000 | F2: 0 | G2: 0 | H2: 621365
A3: MNA002 | B3: CSA_002 | C3: Margined | D3: 11000 | E3: 10000 | F3: 0 | G3: 0 | H3: 2901185.2
A4: MNA003 | B4: CSA_003 | C4: Unmargined | D4: 110000 | H4: 2304025.7
A5: MNA004 | B5: CSA_004 | C5: Margined | D5: 110000 | E5: 200000 | F5: 0 | G5: 0 | H5: 637373.54
A6: MNA005 | B6: CSA_005 | C6: Margined | D6: 11000 | E6: 10000 | F6: 0 | G6: 0 | H6: 2901185.2
A7: MNA006 | B7: CSA_006 | C7: Margined | D7: 426500 | E7: 650000 | F7: 0 | G7: 0 | H7: 18534.749

Sheet parameters
A1: Asset_class | B1: Category | C1: Type | D1: Option_volatility | E1: Correlation_factor | F1: Supervisory_factor
A2: Interest rate | B2: N/A | C2: N/A | D2: 0.5 | F2: 0.005
A3: Exchange rate | B3: N/A | C3: N/A | D3: 0.15 | F3: 0.04
A4: Credit, single name | B4: Investment grade | C4: N/A | D4: 1 | E4: 0.5 | F4: 0.0046
A5: Credit, single name | B5: Speculative grade | C5: N/A | D5: 1 | E5: 0.5 | F5: 0.013
A6: Credit, single name | B6: Sub-speculative grade | C6: N/A | D6: 1 | E6: 0.5 | F6: 0.06
A7: Credit, index | B7: Investment grade | C7: N/A | D7: 0.8 | E7: 0.8 | F7: 0.0038
A8: Credit, index | B8: Speculative grade | C8: N/A | D8: 0.8 | E8: 0.8 | F8: 0.0106
A9: Equity, single name | B9: N/A | C9: N/A | D9: 1.2 | E9: 0.5 | F9: 0.32
A10: Equity, index | B10: N/A | C10: N/A | D10: 0.75 | E10: 0.8 | F10: 0.2
A11: Commodity | B11: Energy | C11: Electricity | D11: 1.5 | E11: 0.4 | F11: 0.4
A12: Commodity | B12: Energy | C12: Other | D12: 0.7 | E12: 0.4 | F12: 0.18
A13: Commodity | B13: Metals | C13: N/A | D13: 0.7 | E13: 0.4 | F13: 0.18
A14: Commodity | B14: Agricultural | C14: N/A | D14: 0.7 | E14: 0.4 | F14: 0.18
A15: Commodity | B15: Other | C15: N/A | D15: 0.7 | E15: 0.4 | F15: 0.18

Sheet MPOR matrix
A1: MPOR | B1: is_client_facing | C1: margin frequency (BD) | D1: is_large_netting_set | E1: ns_has_difficult_to_replace_trade | F1: ns_has_illiquid_collateral | G1: margin_dispute
A2: =IF(G2="Y",2,1)*IF(OR(D2="Y",E2="Y",F2="Y"),20,IF(B2="Y",5,10))+C2-1 -> 10 | B2: N | C2: 1 | D2: N | E2: N | F2: N | G2: N
A3: =IF(G3="Y",2,1)*IF(OR(D3="Y",E3="Y",F3="Y"),20,IF(B3="Y",5,10))+C3-1 -> 20 | B3: N | C3: 1 | D3: N | E3: N | F3: N | G3: Y
A4: =IF(G4="Y",2,1)*IF(OR(D4="Y",E4="Y",F4="Y"),20,IF(B4="Y",5,10))+C4-1 -> 20 | B4: N | C4: 1 | D4: N | E4: N | F4: Y | G4: N
A5: =IF(G5="Y",2,1)*IF(OR(D5="Y",E5="Y",F5="Y"),20,IF(B5="Y",5,10))+C5-1 -> 40 | B5: N | C5: 1 | D5: N | E5: N | F5: Y | G5: Y
A6: =IF(G6="Y",2,1)*IF(OR(D6="Y",E6="Y",F6="Y"),20,IF(B6="Y",5,10))+C6-1 -> 20 | B6: N | C6: 1 | D6: N | E6: Y | F6: N | G6: N
A7: =IF(G7="Y",2,1)*IF(OR(D7="Y",E7="Y",F7="Y"),20,IF(B7="Y",5,10))+C7-1 -> 40 | B7: N | C7: 1 | D7: N | E7: Y | F7: N | G7: Y
A8: =IF(G8="Y",2,1)*IF(OR(D8="Y",E8="Y",F8="Y"),20,IF(B8="Y",5,10))+C8-1 -> 20 | B8: N | C8: 1 | D8: N | E8: Y | F8: Y | G8: N
A9: =IF(G9="Y",2,1)*IF(OR(D9="Y",E9="Y",F9="Y"),20,IF(B9="Y",5,10))+C9-1 -> 40 | B9: N | C9: 1 | D9: N | E9: Y | F9: Y | G9: Y
A10: =IF(G10="Y",2,1)*IF(OR(D10="Y",E10="Y",F10="Y"),20,IF(B10="Y",5,10))+C10-1 -> 20 | B10: N | C10: 1 | D10: Y | E10: N | F10: N | G10: N
A11: =IF(G11="Y",2,1)*IF(OR(D11="Y",E11="Y",F11="Y"),20,IF(B11="Y",5,10))+C11-1 -> 40 | B11: N | C11: 1 | D11: Y | E11: N | F11: N | G11: Y
A12: =IF(G12="Y",2,1)*IF(OR(D12="Y",E12="Y",F12="Y"),20,IF(B12="Y",5,10))+C12-1 -> 20 | B12: N | C12: 1 | D12: Y | E12: N | F12: Y | G12: N
A13: =IF(G13="Y",2,1)*IF(OR(D13="Y",E13="Y",F13="Y"),20,IF(B13="Y",5,10))+C13-1 -> 40 | B13: N | C13: 1 | D13: Y | E13: N | F13: Y | G13: Y
... A225: =IF(G225="Y",2,1)*IF(OR(D225="Y",E225="Y",F225="Y"),20,IF(B225="Y",5,10))+C225-1 -> 289 | B225: Y | C225: 250 | D225: Y | E225: Y | F225: Y | G225: Y

Sheet MNA006
A1: Trade_ID | B1: Trade_001 | D1: Delta = -3 | G1: Delta = corrected
A2: Netting_ID | B2: MNA006 | G2: delta recal | H2: =-_xlfn.NORM.S.DIST((LN(B16/B17)+(parameters!D10)^2*'MNA006'!B18/250)/(SQRT(250/250)*'MNA006'!B18),TRUE) -> -0.50089762
A3: Underlying_ticker | B3: STOXX50 | D3: Maturity factor | E3: =1.5*SQRT(B10/250) -> 0.3 | G3: Maturity factor | H3: =1.5*SQRT(B10/250) -> 0.3
A4: Long_Short | B4: Short | D4: ADCA | E4: =B9*B26*parameters!F10*E3 -> -925050.24 | G4: ADCA | H4: =B9*H2*parameters!F10*E3 -> -154451.82
A5: Asset_class | B5: Equity, index | D5: addon | E5: =ABS(E4) -> 925050.24 | G5: addon | H5: =ABS(H4) -> 154451.82
A6: Category | B6: N/A | D6: V | E6: =B8 -> -459120 | G6: V | H6: =E6 -> -459120
A7: Type | B7: N/A | D7: C | E7: =csa_inputs!D7+csa_inputs!E7 -> 1076500 | G7: C | H7: =E7 -> 1076500
A8: Market_value | B8: -459120 | D8: PFE multiplier | E8: =MIN(1,5%+95%*EXP((E6-E7)/1.9*E5)) -> 0.05 | G8: PFE multiplier | H8: =MIN(1,5%+95%*EXP((H6-H7)/1.9*H5)) -> 0.05
A9: Trade_notional | B9: 5139168 | D9: PFE | E9: =E8*E5 -> 46252.512 | G9: PFE | H9: =H8*H5 -> 7722.5911
A10: MPOR | B10: 10 | D10: RC | E10: =csa_inputs!D7+csa_inputs!E7 -> 1076500 | G10: RC | H10: =E10 -> 1076500
A11: start_date | B11: 0 | D11: EAD | E11: =1.4*SUM(E9:E10) -> 1571853.5 | G11: EAD | H11: =SUM(H9:H10)*1.4 -> 1517911.6
A12: end_date | B12: 250
A13: Maturity | B13: 250
A14: is_option | B14: TRUE
A15: Call_Put | B15: Call
A16: Underlying_price | B16: 4282.64
A17: Strike_price | B17: 4282.64
A18: Option_maturity | B18: 250
A19: is_CDO_tranches | B19: FALSE
A20: Attachment_Point
A21: Detachment_Point
A22: is_volatility_trade | B22: FALSE
A23: is_basis_trade | B23: FALSE
A24: COB_date | B24: 45838
A25: System_end_date | B25: =B24+B12 -> 46088
A26: System_delta | B26: -3
A27: is_client_facing | B27: N
A28: margin frequency (BD) | B28: 1
A29: is_large_netting_set | B29: N
A30: ns_has_difficult_to_replace_trade | B30: N
A31: ns_has_illiquid_collateral | B31: N
A32: margin_dispute | B32: N
